<?xml version="1.0" ?>
<!-- =================================================================================== -->
<!-- |    This document was autogenerated by xacro from bigbot3.xacro                  | -->
<!-- |    EDITING THIS FILE BY HAND IS NOT RECOMMENDED                                 | -->
<!-- =================================================================================== -->
<robot name="bigbot" xmlns:controller="http://playerstage.sourceforge.net/gazebo/xmlschema/#controller" xmlns:interface="http://playerstage.sourceforge.net/gazebo/xmlschema/#interface" xmlns:sensor="http://playerstage.sourceforge.net/gazebo/xmlschema/#sensor" xmlns:xacro="http://www.ros.org/wiki/xacro">
  <!-- Defining the colors used in this robot -->
  <material name="Black">
    <color rgba="0.0 0.0 0.0 1.0"/>
  </material>
  <material name="Red">
    <color rgba="0.8 0.0 0.0 1.0"/>
  </material>
  <material name="White">
    <color rgba="1.0 1.0 1.0 1.0"/>
  </material>
  <material name="Blue">
    <color rgba="0.0 0.0 0.8 1.0"/>
  </material>
  <material name="Green">
    <color rgba="0.0 1.0 0.0 1.0"/>
  </material>
  <!-- per https://en.wikipedia.org/wiki/List_of_moments_of_inertia 
	  ixx = m/12(h * h  + d * d)
	  iyy = m/12(w * w  + d * d)
	  izz= m/12(w * w  + h * h)
	 -->
  <!-- per https://answers.ros.org/question/39107/urdf-link-mass-inertia-prop 
		origin should be from baselink origin to center of mass.
		which  is half way from axil (baselink) to caster attachment
		which I estimate is 9 inches -->
  <!-- base_footprint is a fictitious link(frame) that is on the ground right below base_link origin -->
  <!-- 		<xacro:default_inertial mass="0.0001"/> error said to remove this from footprint-->
  <link name="base_footprint">
    <visual>
      <geometry>
        <box size="0.001 0.001 0.001"/>
      </geometry>
      <origin rpy="0 0 0" xyz="0 0 0"/>
      <material name="Red"/>
    </visual>
    <inertial>
      <mass value="0.0001"/>
      <inertia ixx="1.0" ixy="0.0" ixz="0.0" iyy="1.0" iyz="0.0" izz="1.0"/>
    </inertial>
  </link>
  <gazebo reference="base_footprint">
    <material>Gazebo/Red</material>
    <turnGravityOff>false</turnGravityOff>
  </gazebo>
  <joint name="base_footprint_joint" type="fixed">
    <origin rpy="0 0 0" xyz="0 0 0.09763"/>
    <parent link="base_footprint"/>
    <child link="base_link"/>
  </joint>
  <link name="base_link">
    <visual>
      <geometry>
        <box size="0.635 0.635 0.1524"/>
      </geometry>
      <!-- per http://wiki.ros.org/urdf/XML/link a box's origin is the center of the box 
			so the way I understand this is we need to offset from the axil to the center of my base 
			to have the box show up right 
			I am estimating I have 3 inches in front of my axil (where I want baseink to be)
			which I think leaves 9 inches to the center of the box 
			I think this needs to be negative
			-->
      <origin rpy="0 0 0" xyz="-0.22 0 0.1524"/>
      <material name="White"/>
    </visual>
    <collision>
      <geometry>
        <box size="0.635 0.635 0.1524"/>
      </geometry>
      <origin rpy="0 0 0" xyz="-0.22 0 0"/>
    </collision>
    <inertial>
      <mass value="12"/>
      <inertia ixx="0.42645076" ixy="0" ixz="0" iyy="0.42645076" iyz="0" izz="0.80645"/>
      <origin xyz="-0.22 0 0"/>
    </inertial>
  </link>
  <gazebo reference="base_link">
    <material>Gazebo/White</material>
    <turnGravityOff>false</turnGravityOff>
  </gazebo>
  <link name="left_wheel">
    <visual>
      <geometry>
        <cylinder length="0.0682625" radius="0.09763"/>
      </geometry>
      <origin rpy="0 0 0" xyz="0 0 0"/>
      <material name="Green"/>
    </visual>
    <collision>
      <geometry>
        <cylinder length="0.1000125" radius="0.09763"/>
      </geometry>
    </collision>
    <inertial>
      <mass value="1"/>
      <inertia ixx="0.00277121830052" ixy="0" ixz="0" iyy="0.00277121830052" iyz="0" izz="0.00476580845"/>
    </inertial>
  </link>
  <gazebo reference="left_wheel">
    <turnGravityOff>false</turnGravityOff>
  </gazebo>
  <link name="right_wheel">
    <visual>
      <geometry>
        <cylinder length="0.0682625" radius="0.09763"/>
      </geometry>
      <origin rpy="0 0 0" xyz="0 0 0"/>
      <material name="Black"/>
    </visual>
    <collision>
      <geometry>
        <cylinder length="0.1000125" radius="0.09763"/>
      </geometry>
    </collision>
    <inertial>
      <mass value="1"/>
      <inertia ixx="0.00277121830052" ixy="0" ixz="0" iyy="0.00277121830052" iyz="0" izz="0.00476580845"/>
    </inertial>
  </link>
  <gazebo reference="right_wheel">
    <turnGravityOff>false</turnGravityOff>
  </gazebo>
  <joint name="base_to_left_wheel" type="continuous">
    <parent link="base_link"/>
    <child link="left_wheel"/>
    <origin rpy="1.5707 0 0" xyz="0 0.38354 0"/>
    <axis xyz="0 0 1"/>
  </joint>
  <joint name="base_to_right_wheel" type="continuous">
    <parent link="base_link"/>
    <child link="right_wheel"/>
    <origin rpy="1.5707 0 0" xyz="0 -0.38354 0"/>
    <axis xyz="0 0 1"/>
  </joint>
  <!--Caster Back  -->
  <link name="caster_link">
    <visual>
      <origin rpy="1.57079632679 0 0" xyz="0 0 0"/>
      <geometry>
        <sphere radius="0.05715"/>
      </geometry>
      <material name="Blue"/>
    </visual>
    <collision>
      <geometry>
        <sphere radius="0.05715"/>
      </geometry>
      <origin rpy="1.57079632679 0 0" xyz="0 0. 0"/>
    </collision>
    <inertial>
      <mass value="1"/>
      <origin xyz="0 0 0"/>
      <inertia ixx="0.001" ixy="0.0" ixz="0.0" iyy="0.001" iyz="0.0" izz="0.001"/>
    </inertial>
  </link>
  <joint name="caster_joint" type="fixed">
    <parent link="base_link"/>
    <child link="caster_link"/>
    <origin rpy="0 0 0" xyz="-0.4948 0.0 -0.04048"/>
  </joint>
  <!-- R was ${-M_PI/2} -->
  <!-- laser joint -->
  <joint name="laser_joint" type="fixed">
    <origin rpy="0 0 0" xyz="0.0635 0.0 -0.0127"/>
    <parent link="base_link"/>
    <axis xyz="0 1 0"/>
    <child link="laser_point"/>
  </joint>
  <!-- laser joint -->
  <joint name="laser_rotate" type="fixed">
    <origin rpy="3.14 0 -1.57" xyz="0 0 0"/>
    <parent link="laser_point"/>
    <axis xyz="0 1 0"/>
    <child link="laser_frame"/>
  </joint>
  <link name="laser_point">
    <collision>
      <origin rpy="0 0 0" xyz="0 0 0"/>
      <geometry>
        <cylinder length=".0001" radius="0.0001"/>
      </geometry>
    </collision>
    <visual>
      <origin rpy="0 0 0" xyz="0 0 0"/>
      <geometry>
        <cylinder length=".0001" radius="0.0001"/>
      </geometry>
      <material name="Blue"/>
    </visual>
    <inertial>
      <mass value="1e-5"/>
      <origin rpy="0 0 0" xyz="0 0 0"/>
      <inertia ixx="1e-6" ixy="0" ixz="0" iyy="1e-6" iyz="0" izz="1e-6"/>
    </inertial>
  </link>
  <!-- sweep Laser -->
  <link name="laser_frame">
    <collision>
      <origin rpy="0 0 0" xyz="0 0 0"/>
      <geometry>
        <cylinder length=".0508" radius="0.0635"/>
      </geometry>
    </collision>
    <visual>
      <origin rpy="0 0 0" xyz="0 0 0"/>
      <geometry>
        <cylinder length=".0508" radius="0.0635"/>
      </geometry>
      <material name="Blue"/>
    </visual>
    <inertial>
      <mass value="1e-5"/>
      <origin rpy="0 0 0" xyz="0 0 0"/>
      <inertia ixx="1e-6" ixy="0" ixz="0" iyy="1e-6" iyz="0" izz="1e-6"/>
    </inertial>
  </link>
  <gazebo reference="caster_link">
    <turnGravityOff>false</turnGravityOff>
  </gazebo>
  <!-- Differential drive controller  -->
  <gazebo>
    <plugin filename="libgazebo_ros_diff_drive.so" name="differential_drive_controller">
      <rosDebugLevel>Debug</rosDebugLevel>
      <publishWheelTF>false</publishWheelTF>
      <robotNamespace>/</robotNamespace>
      <publishTf>1</publishTf>
      <publishWheelJointState>false</publishWheelJointState>
      <alwaysOn>true</alwaysOn>
      <updateRate>100.0</updateRate>
      <leftJoint>base_to_left_wheel</leftJoint>
      <rightJoint>base_to_right_wheel</rightJoint>
      <wheelSeparation>0.76708</wheelSeparation>
      <wheelDiameter>0.19526</wheelDiameter>
      <broadcastTF>1</broadcastTF>
      <wheelTorque>30</wheelTorque>
      <wheelAcceleration>1.8</wheelAcceleration>
      <commandTopic>cmd_vel</commandTopic>
      <odometryFrame>odom</odometryFrame>
      <odometryTopic>odom</odometryTopic>
      <robotBaseFrame>base_footprint</robotBaseFrame>
    </plugin>
  </gazebo>
</robot>
